Workbook

Sheet Inputs
A1: 0.01 | Z1: RateList | AA1: OwnList | AB1: FilingStatusList
Z2: 0 | AA2: 0 | AB2: Single
A3: PROFILE | Z3: 0.0025 | AA3: 0.1 | AB3: Married Filing Jointly
A4: Primary DOB | B4: 32143 | C4: (edit if needed) | Z4: 0.005 | AA4: 0.2 | AB4: Married Filing Separately
A5: Current Age | B5: 38 | Z5: 0.0075 | AA5: 0.3 | AB5: Head of Household
A6: Filing Status | B6: Married Filing Jointly | C6: Surviving spouse: QSS up to 2 yrs, then Single/HoH | Z6: 0.01 | AA6: 0.4 | AB6: Qualifying Surviving Spouse
A7: State | B7: Florida | Z7: 0.0125 | AA7: 0.5
A8: Target Retirement Age | B8: 65 | Z8: 0.015 | AA8: 0.6
A9: Planning Horizon Age | B9: 85 | Z9: 0.0175 | AA9: 0.7
Z10: 0.02 | AA10: 0.8
A11: MARKET ASSUMPTIONS | Z11: 0.0225 | AA11: 0.9
A12: Expected Inflation | B12: 0.03 | Z12: 0.025 | AA12: 1
A13: Expected Portfolio Return | B13: 0.06 | Z13: 0.0275
A14: Safe Withdrawal Rate (SWR) | B14: 0.04 | Z14: 0.03
A15: Monthly Rent / Property Income | B15: 0 | Z15: 0.0325
Z16: 0.035
A17: TARGET PORTFOLIO BALANCES (at retirement) | Z17: 0.0375
A18: Target — Brokerage_01 | B18: 1500000 | Z18: 0.04
A19: Target — Brokerage_02 | B19: 0 | Z19: 0.0425
A20: Target — 401K | B20: 1000000 | Z20: 0.045
A21: Target — Brokerage_03 | B21: 0 | Z21: 0.0475
A22: Target — IRA | B22: 0 | Z22: 0.05
A23: Target — Roth IRA | B23: 0 | Z23: 0.0525
A24: Total Target Investable | B24: =SUM(B18:B23) -> 2500000 | Z24: 0.055
Z25: 0.0575
A26: PROPERTY OWNERSHIP % | Z26: 0.06
A27: Real_Estate_01 | B27: 1 | Z27: 0.0625
A28: Real_Estate_02 | B28: 1 | Z28: 0.065
A29: Real_Estate_03 | B29: 1 | Z29: 0.0675
A30: Real_Estate_04 | B30: 1 | Z30: 0.07
A31: Real_Estate_05 | B31: 1 | Z31: 0.0725
A32: Real_Estate_06 | B32: 1 | Z32: 0.075
Z33: 0.0775
Z34: 0.08
Z35: 0.0825
Z36: 0.085
Z37: 0.0875
Z38: 0.09
Z39: 0.0925
Z40: 0.095
...

Sheet Accounts
A1: 0.01
A3: Account ID | B3: Account Name | C3: Tax Type | D3: Category | E3: Owner | F3: Ownership % | G3: RMD Eligible | H3: Roth Conversion Source | I3: Withdrawal Priority Note | J3: Active
A4: Account_01 | B4: Brokerage_01 | C4: Brokerage | D4: Liquid | E4: Primary | F4: 1 | G4: No | H4: No | I4: Taxable gains — prefer LTCG harvesting | J4: Yes
A5: Account_02 | B5: Brokerage_02 | C5: Brokerage | D5: Liquid | E5: Primary | F5: 1 | G5: No | H5: No | I5: Taxable — coordinate with tax bracket | J5: Yes
A6: Account_03 | B6: 401K | C6: Traditional 401k | D6: Liquid | E6: Primary | F6: 1 | G6: Yes | H6: Yes | I6: Pre-tax — RMD + Roth conversion candidate | J6: Yes
A7: Account_04 | B7: Cash | C7: Cash | D7: Liquid | E7: Primary | F7: 1 | G7: No | H7: No | I7: Liquidity buffer — first for spending | J7: Yes
A8: Account_05 | B8: Other | C8: Other | D8: Other | E8: Primary | F8: 1 | G8: No | H8: No | I8: Other asset — classify further if needed | J8: Yes
A9: Account_06 | B9: Brokerage_03 | C9: Brokerage | D9: Liquid | E9: Primary | F9: 1 | G9: No | H9: No | I9: Taxable brokerage | J9: Yes
A10: Account_07 | B10: Brokerage_04 | C10: Brokerage | D10: Liquid | E10: Primary | F10: 1 | G10: No | H10: No | I10: Taxable / alt brokerage | J10: Yes
A11: Account_08 | B11: IRA | C11: Traditional IRA | D11: Liquid | E11: Primary | F11: 1 | G11: Yes | H11: Yes | I11: Placeholder — add when opened | J11: No
A12: Account_09 | B12: Roth_IRA | C12: Roth IRA | D12: Liquid | E12: Primary | F12: 1 | G12: No | H12: No | I12: Tax-free — last resort / legacy; conversion target | J12: No
A13: Account_10 | B13: Real_Estate_01 | C13: Real Estate | D13: Property | E13: Primary | F13: =Inputs!B27 -> 1 | G13: No | H13: No | I13: Illiquid — equity only in NW | J13: Yes
A14: Account_11 | B14: Real_Estate_02 | C14: Real Estate | D14: Property | E14: Primary | F14: =Inputs!B28 -> 1 | G14: No | H14: No | I14: Illiquid | J14: Yes
A15: Account_12 | B15: Real_Estate_03 | C15: Real Estate | D15: Property | E15: Primary | F15: =Inputs!B29 -> 1 | G15: No | H15: No | I15: Illiquid | J15: Yes
A16: Account_13 | B16: Real_Estate_04 | C16: Real Estate | D16: Property | E16: Primary | F16: =Inputs!B30 -> 1 | G16: No | H16: No | I16: Illiquid | J16: Yes
A17: Account_14 | B17: Real_Estate_05 | C17: Real Estate | D17: Property | E17: Primary | F17: =Inputs!B31 -> 1 | G17: No | H17: No | I17: Illiquid | J17: Yes
A18: Account_15 | B18: Real_Estate_06 | C18: Real Estate | D18: Property | E18: Primary | F18: =Inputs!B32 -> 1 | G18: No | H18: No | I18: Illiquid | J18: Yes
A20: TAX TYPE LEGEND (for app logic)
A21: Cash | B21: No RMD; ordinary income on interest; first spend source
A22: Brokerage | B22: No RMD; LTCG/qualified dividends; basis tracking later
A23: Traditional 401k / IRA | B23: RMD from RMD age; ordinary income; Roth conversion source
A24: Roth IRA | B24: No lifetime RMD (owner); tax-free qualified; conversion destination
A25: Real Estate | B25: Illiquid; rental income separate; not in SWR portfolio by default
A26: Other | B26: Manual treatment — refine before withdrawal engine

Sheet Monthly Balances
A1: Monthly Account Balances — Enter blue cells each month | $ actual
A2: LIQUID / INVESTMENT ACCOUNTS
A3: Date | B3: Brokerage_01 (IND) | C3: Brokerage_02 (ROTH) | D3: 401K | E3: Cash | F3: Other | G3: Brokerage_03 (FID 529) | H3: Brokerage_04 | I3: IRA | J3: Roth_IRA | K3: Total Liquid | L3: Brokerage | M3: Pre-Tax | N3: Roth | O3: Cash | P3: MoM Δ | Q3: YoY Δ | R3: MoM % | S3: Age | T3: Real_Estate_01 | U3: Real_Estate_02 | V3: Real_Estate_03 | W3: Real_Estate_04 | X3: Real_Estate_05 | Y3: Real_Estate_06 | Z3: Prop Equity | AA3: Net Worth | AB3: Date | AC3: Total Liquid
A4: 45505 | B4: 173.67 | C4: 1.46 | D4: 173758.4 | E4: 59874 | F4: 0 | G4: 583 | H4: 0 | I4: 0 | J4: 0 | K4: =SUM(B4:J4) -> 234390.53 | L4: =B4+C4+G4+H4 -> 758.13 | M4: =D4+I4 -> 173758.4 | N4: =J4 -> 0 | O4: =E4 -> 59874 | S4: =IF(A4="","",DATEDIF(Inputs!$B$4,A4,"Y")) -> 36 | X4: 600000 | Z4: =T4*Inputs!$B$27+U4*Inputs!$B$28+V4*Inputs!$B$29+W4*Inputs!$B$30+X4*Inputs!$B$31+Y4*Inputs!$B$32 -> 600000 | AA4: =K4+Z4 -> 834390.53 | AB4: =A4 -> 45505 | AC4: =K4 -> 234390.53
A5: 45536 | B5: 674.4 | C5: 285.77 | D5: 175750.95 | E5: 59965.63 | F5: 0 | G5: 719.83 | H5: 180 | I5: 300 | J5: 225 | K5: =SUM(B5:J5) -> 238101.58 | L5: =B5+C5+G5+H5 -> 1860 | M5: =D5+I5 -> 176050.95 | N5: =J5 -> 225 | O5: =E5 -> 59965.63 | P5: =K5-K4 -> 3711.05 | R5: =IFERROR(P5/K4,"") -> 0.015832764 | S5: =IF(A5="","",DATEDIF(Inputs!$B$4,A5,"Y")) -> 36 | T5: 0 | U5: 0 | V5: 0 | W5: 0 | X5: 600000 | Y5: 0 | Z5: =T5*Inputs!$B$27+U5*Inputs!$B$28+V5*Inputs!$B$29+W5*Inputs!$B$30+X5*Inputs!$B$31+Y5*Inputs!$B$32 -> 600000 | AA5: =K5+Z5 -> 838101.58 | AB5: =A5 -> 45536 | AC5: =K5 -> 238101.58
A6: 45566 | B6: 1105.51 | C6: 502.73 | D6: 177749.76 | E6: 59980.96 | F6: 0 | G6: 841.19 | H6: 360 | I6: 600 | J6: 450 | K6: =SUM(B6:J6) -> 241590.15 | L6: =B6+C6+G6+H6 -> 2809.43 | M6: =D6+I6 -> 178349.76 | N6: =J6 -> 450 | O6: =E6 -> 59980.96 | P6: =K6-K5 -> 3488.57 | R6: =IFERROR(P6/K5,"") -> 0.014651604 | S6: =IF(A6="","",DATEDIF(Inputs!$B$4,A6,"Y")) -> 36 | T6: 0 | U6: 0 | V6: 0 | W6: 0 | X6: 600000 | Y6: 0 | Z6: =T6*Inputs!$B$27+U6*Inputs!$B$28+V6*Inputs!$B$29+W6*Inputs!$B$30+X6*Inputs!$B$31+Y6*Inputs!$B$32 -> 600000 | AA6: =K6+Z6 -> 841590.15 | AB6: =A6 -> 45566 | AC6: =K6 -> 241590.15
A7: 45597 | B7: 1461.37 | C7: 736.91 | D7: 179754.85 | E7: 59862.37 | F7: 725 | G7: 945.82 | H7: 540 | I7: 900 | J7: 675 | K7: =SUM(B7:J7) -> 245601.32 | L7: =B7+C7+G7+H7 -> 3684.1 | M7: =D7+I7 -> 180654.85 | N7: =J7 -> 675 | O7: =E7 -> 59862.37 | P7: =K7-K6 -> 4011.17 | R7: =IFERROR(P7/K6,"") -> 0.016603202 | S7: =IF(A7="","",DATEDIF(Inputs!$B$4,A7,"Y")) -> 36 | T7: 0 | U7: 0 | V7: 0 | W7: 0 | X7: 600000 | Y7: 0 | Z7: =T7*Inputs!$B$27+U7*Inputs!$B$28+V7*Inputs!$B$29+W7*Inputs!$B$30+X7*Inputs!$B$31+Y7*Inputs!$B$32 -> 600000 | AA7: =K7+Z7 -> 845601.32 | AB7: =A7 -> 45597 | AC7: =K7 -> 245601.32
A8: 45627 | B8: 1805.56 | C8: 1012.05 | D8: 181766.28 | E8: 59585.04 | F8: 0 | G8: 1047.86 | H8: 720 | I8: 1200 | J8: 900 | K8: =SUM(B8:J8) -> 248036.79 | L8: =B8+C8+G8+H8 -> 4585.47 | M8: =D8+I8 -> 182966.28 | N8: =J8 -> 900 | O8: =E8 -> 59585.04 | P8: =K8-K7 -> 2435.47 | R8: =IFERROR(P8/K7,"") -> 0.0099163555 | S8: =IF(A8="","",DATEDIF(Inputs!$B$4,A8,"Y")) -> 36 | T8: 0 | U8: 0 | V8: 0 | W8: 0 | X8: 600000 | Y8: 0 | Z8: =T8*Inputs!$B$27+U8*Inputs!$B$28+V8*Inputs!$B$29+W8*Inputs!$B$30+X8*Inputs!$B$31+Y8*Inputs!$B$32 -> 600000 | AA8: =K8+Z8 -> 848036.79 | AB8: =A8 -> 45627 | AC8: =K8 -> 248036.79
A9: 45658 | B9: 2212.37 | C9: 1314.22 | D9: 183784.08 | E9: 59163.01 | F9: 0 | G9: 1163.82 | H9: 900 | I9: 1500 | J9: 1125 | K9: =SUM(B9:J9) -> 251162.5 | L9: =B9+C9+G9+H9 -> 5590.41 | M9: =D9+I9 -> 185284.08 | N9: =J9 -> 1125 | O9: =E9 -> 59163.01 | P9: =K9-K8 -> 3125.71 | R9: =IFERROR(P9/K8,"") -> 0.0126018 | S9: =IF(A9="","",DATEDIF(Inputs!$B$4,A9,"Y")) -> 37 | T9: 0 | U9: 0 | V9: 0 | W9: 0 | X9: 600000 | Y9: 0 | Z9: =T9*Inputs!$B$27+U9*Inputs!$B$28+V9*Inputs!$B$29+W9*Inputs!$B$30+X9*Inputs!$B$31+Y9*Inputs!$B$32 -> 600000 | AA9: =K9+Z9 -> 851162.5 | AB9: =A9 -> 45658 | AC9: =K9 -> 251162.5
A10: 45689 | B10: 2698.52 | C10: 1604.67 | D10: 185808.29 | E10: 58645.73 | F10: 950 | G10: 1297.41 | H10: 1080 | I10: 1800 | J10: 1350 | K10: =SUM(B10:J10) -> 255234.62 | L10: =B10+C10+G10+H10 -> 6680.6 | M10: =D10+I10 -> 187608.29 | N10: =J10 -> 1350 | O10: =E10 -> 58645.73 | P10: =K10-K9 -> 4072.12 | R10: =IFERROR(P10/K9,"") -> 0.016213089 | S10: =IF(A10="","",DATEDIF(Inputs!$B$4,A10,"Y")) -> 37 | T10: 0 | U10: 0 | V10: 0 | W10: 0 | X10: 600000 | Y10: 0 | Z10: =T10*Inputs!$B$27+U10*Inputs!$B$28+V10*Inputs!$B$29+W10*Inputs!$B$30+X10*Inputs!$B$31+Y10*Inputs!$B$32 -> 600000 | AA10: =K10+Z10 -> 855234.62 | AB10: =A10 -> 45689 | AC10: =K10 -> 255234.62
A11: 45717 | B11: 3207.8 | C11: 1855.39 | D11: 187838.94 | E11: 58105.99 | F11: 0 | G11: 1436.14 | H11: 1260 | I11: 2100 | J11: 1575 | K11: =SUM(B11:J11) -> 257379.26 | L11: =B11+C11+G11+H11 -> 7759.33 | M11: =D11+I11 -> 189938.94 | N11: =J11 -> 1575 | O11: =E11 -> 58105.99 | P11: =K11-K10 -> 2144.64 | R11: =IFERROR(P11/K10,"") -> 0.0084026219 | S11: =IF(A11="","",DATEDIF(Inputs!$B$4,A11,"Y")) -> 37 | T11: 0 | U11: 0 | V11: 0 | W11: 0 | X11: 600000 | Y11: 0 | Z11: =T11*Inputs!$B$27+U11*Inputs!$B$28+V11*Inputs!$B$29+W11*Inputs!$B$30+X11*Inputs!$B$31+Y11*Inputs!$B$32 -> 600000 | AA11: =K11+Z11 -> 857379.26 | AB11: =A11 -> 45717 | AC11: =K11 -> 257379.26
A12: 45748 | B12: 3662.71 | C12: 2074.91 | D12: 189876.07 | E12: 57622.08 | F12: 0 | G12: 1562.79 | H12: 1440 | I12: 2400 | J12: 1800 | K12: =SUM(B12:J12) -> 260438.56 | L12: =B12+C12+G12+H12 -> 8740.41 | M12: =D12+I12 -> 192276.07 | N12: =J12 -> 1800 | O12: =E12 -> 57622.08 | P12: =K12-K11 -> 3059.3 | R12: =IFERROR(P12/K11,"") -> 0.01188635 | S12: =IF(A12="","",DATEDIF(Inputs!$B$4,A12,"Y")) -> 37 | T12: 0 | U12: 0 | V12: 0 | W12: 0 | X12: 600000 | Y12: 0 | Z12: =T12*Inputs!$B$27+U12*Inputs!$B$28+V12*Inputs!$B$29+W12*Inputs!$B$30+X12*Inputs!$B$31+Y12*Inputs!$B$32 -> 600000 | AA12: =K12+Z12 -> 860438.56 | AB12: =A12 -> 45748 | AC12: =K12 -> 260438.56
A13: 45778 | B13: 4035.76 | C13: 2300.46 | D13: 191919.73 | E13: 57258.61 | F13: 1175 | G13: 1671.24 | H13: 1620 | I13: 2700 | J13: 2025 | K13: =SUM(B13:J13) -> 264705.8 | L13: =B13+C13+G13+H13 -> 9627.46 | M13: =D13+I13 -> 194619.73 | N13: =J13 -> 2025 | O13: =E13 -> 57258.61 | P13: =K13-K12 -> 4267.24 | R13: =IFERROR(P13/K12,"") -> 0.016384824 | S13: =IF(A13="","",DATEDIF(Inputs!$B$4,A13,"Y")) -> 37 | T13: 0 | U13: 0 | V13: 0 | W13: 0 | X13: 600000 | Y13: 0 | Z13: =T13*Inputs!$B$27+U13*Inputs!$B$28+V13*Inputs!$B$29+W13*Inputs!$B$30+X13*Inputs!$B$31+Y13*Inputs!$B$32 -> 600000 | AA13: =K13+Z13 -> 864705.8 | AB13: =A13 -> 45778 | AC13: =K13 -> 264705.8
A14: 45809 | B14: 4374.71 | C14: 2563.7 | D14: 193969.94 | E14: 57050.7 | F14: 0 | G14: 1772.12 | H14: 1800 | I14: 3000 | J14: 2250 | K14: =SUM(B14:J14) -> 266781.17 | L14: =B14+C14+G14+H14 -> 10510.53 | M14: =D14+I14 -> 196969.94 | N14: =J14 -> 2250 | O14: =E14 -> 57050.7 | P14: =K14-K13 -> 2075.37 | R14: =IFERROR(P14/K13,"") -> 0.0078402891 | S14: =IF(A14="","",DATEDIF(Inputs!$B$4,A14,"Y")) -> 37 | T14: 0 | U14: 0 | V14: 0 | W14: 0 | X14: 600000 | Y14: 0 | Z14: =T14*Inputs!$B$27+U14*Inputs!$B$28+V14*Inputs!$B$29+W14*Inputs!$B$30+X14*Inputs!$B$31+Y14*Inputs!$B$32 -> 600000 | AA14: =K14+Z14 -> 866781.17 | AB14: =A14 -> 45809 | AC14: =K14 -> 266781.17
K15: =IF(COUNTA(B15:J15)=0,"",SUM(B15:J15)) | L15: =IF(K15="","",B15+C15+G15+H15) | M15: =IF(K15="","",D15+I15) | N15: =IF(K15="","",J15) | O15: =IF(K15="","",E15) | P15: =IF(OR(K15="",K14=""),"",K15-K14) | Q15: =IF(OR(K15="",#REF!=""),"",K15-#REF!) -> #REF! | R15: =IFERROR(IF(OR(P15="",K14=0),"",P15/K14),"") | S15: =IF(A15="","",DATEDIF(Inputs!$B$4,A15,"Y")) | Z15: =IF(COUNTA(T15:Y15)=0,"",T15*Inputs!$B$27+U15*Inputs!$B$28+V15*Inputs!$B$29+W15*Inputs!$B$30+X15*Inputs!$B$31+Y15*Inputs!$B$32) | AA15: =IF(K15="","",K15+IF(Z15="",0,Z15))
K16: =IF(COUNTA(B16:J16)=0,"",SUM(B16:J16)) | L16: =IF(K16="","",B16+C16+G16+H16) | M16: =IF(K16="","",D16+I16) | N16: =IF(K16="","",J16) | O16: =IF(K16="","",E16) | P16: =IF(OR(K16="",K15=""),"",K16-K15) | Q16: =IF(OR(K16="",#REF!=""),"",K16-#REF!) -> #REF! | R16: =IFERROR(IF(OR(P16="",K15=0),"",P16/K15),"") | S16: =IF(A16="","",DATEDIF(Inputs!$B$4,A16,"Y")) | Z16: =IF(COUNTA(T16:Y16)=0,"",T16*Inputs!$B$27+U16*Inputs!$B$28+V16*Inputs!$B$29+W16*Inputs!$B$30+X16*Inputs!$B$31+Y16*Inputs!$B$32) | AA16: =IF(K16="","",K16+IF(Z16="",0,Z16))
K17: =IF(COUNTA(B17:J17)=0,"",SUM(B17:J17)) | L17: =IF(K17="","",B17+C17+G17+H17) | M17: =IF(K17="","",D17+I17) | N17: =IF(K17="","",J17) | O17: =IF(K17="","",E17) | P17: =IF(OR(K17="",K16=""),"",K17-K16) | Q17: =IF(OR(K17="",K5=""),"",K17-K5) | R17: =IFERROR(IF(OR(P17="",K16=0),"",P17/K16),"") | S17: =IF(A17="","",DATEDIF(Inputs!$B$4,A17,"Y")) | Z17: =IF(COUNTA(T17:Y17)=0,"",T17*Inputs!$B$27+U17*Inputs!$B$28+V17*Inputs!$B$29+W17*Inputs!$B$30+X17*Inputs!$B$31+Y17*Inputs!$B$32) | AA17: =IF(K17="","",K17+IF(Z17="",0,Z17))
K18: =IF(COUNTA(B18:J18)=0,"",SUM(B18:J18)) | L18: =IF(K18="","",B18+C18+G18+H18) | M18: =IF(K18="","",D18+I18) | N18: =IF(K18="","",J18) | O18: =IF(K18="","",E18) | P18: =IF(OR(K18="",K17=""),"",K18-K17) | Q18: =IF(OR(K18="",K6=""),"",K18-K6) | R18: =IFERROR(IF(OR(P18="",K17=0),"",P18/K17),"") | S18: =IF(A18="","",DATEDIF(Inputs!$B$4,A18,"Y")) | Z18: =IF(COUNTA(T18:Y18)=0,"",T18*Inputs!$B$27+U18*Inputs!$B$28+V18*Inputs!$B$29+W18*Inputs!$B$30+X18*Inputs!$B$31+Y18*Inputs!$B$32) | AA18: =IF(K18="","",K18+IF(Z18="",0,Z18))
K19: =IF(COUNTA(B19:J19)=0,"",SUM(B19:J19)) | L19: =IF(K19="","",B19+C19+G19+H19) | M19: =IF(K19="","",D19+I19) | N19: =IF(K19="","",J19) | O19: =IF(K19="","",E19) | P19: =IF(OR(K19="",K18=""),"",K19-K18) | Q19: =IF(OR(K19="",K7=""),"",K19-K7) | R19: =IFERROR(IF(OR(P19="",K18=0),"",P19/K18),"") | S19: =IF(A19="","",DATEDIF(Inputs!$B$4,A19,"Y")) | Z19: =IF(COUNTA(T19:Y19)=0,"",T19*Inputs!$B$27+U19*Inputs!$B$28+V19*Inputs!$B$29+W19*Inputs!$B$30+X19*Inputs!$B$31+Y19*Inputs!$B$32) | AA19: =IF(K19="","",K19+IF(Z19="",0,Z19))
K20: =IF(COUNTA(B20:J20)=0,"",SUM(B20:J20)) | L20: =IF(K20="","",B20+C20+G20+H20) | M20: =IF(K20="","",D20+I20) | N20: =IF(K20="","",J20) | O20: =IF(K20="","",E20) | P20: =IF(OR(K20="",K19=""),"",K20-K19) | Q20: =IF(OR(K20="",K8=""),"",K20-K8) | R20: =IFERROR(IF(OR(P20="",K19=0),"",P20/K19),"") | S20: =IF(A20="","",DATEDIF(Inputs!$B$4,A20,"Y")) | Z20: =IF(COUNTA(T20:Y20)=0,"",T20*Inputs!$B$27+U20*Inputs!$B$28+V20*Inputs!$B$29+W20*Inputs!$B$30+X20*Inputs!$B$31+Y20*Inputs!$B$32) | AA20: =IF(K20="","",K20+IF(Z20="",0,Z20))
K21: =IF(COUNTA(B21:J21)=0,"",SUM(B21:J21)) | L21: =IF(K21="","",B21+C21+G21+H21) | M21: =IF(K21="","",D21+I21) | N21: =IF(K21="","",J21) | O21: =IF(K21="","",E21) | P21: =IF(OR(K21="",K20=""),"",K21-K20) | Q21: =IF(OR(K21="",K9=""),"",K21-K9) | R21: =IFERROR(IF(OR(P21="",K20=0),"",P21/K20),"") | S21: =IF(A21="","",DATEDIF(Inputs!$B$4,A21,"Y")) | Z21: =IF(COUNTA(T21:Y21)=0,"",T21*Inputs!$B$27+U21*Inputs!$B$28+V21*Inputs!$B$29+W21*Inputs!$B$30+X21*Inputs!$B$31+Y21*Inputs!$B$32) | AA21: =IF(K21="","",K21+IF(Z21="",0,Z21))
K22: =IF(COUNTA(B22:J22)=0,"",SUM(B22:J22)) | L22: =IF(K22="","",B22+C22+G22+H22) | M22: =IF(K22="","",D22+I22) | N22: =IF(K22="","",J22) | O22: =IF(K22="","",E22) | P22: =IF(OR(K22="",K21=""),"",K22-K21) | Q22: =IF(OR(K22="",K10=""),"",K22-K10) | R22: =IFERROR(IF(OR(P22="",K21=0),"",P22/K21),"") | S22: =IF(A22="","",DATEDIF(Inputs!$B$4,A22,"Y")) | Z22: =IF(COUNTA(T22:Y22)=0,"",T22*Inputs!$B$27+U22*Inputs!$B$28+V22*Inputs!$B$29+W22*Inputs!$B$30+X22*Inputs!$B$31+Y22*Inputs!$B$32) | AA22: =IF(K22="","",K22+IF(Z22="",0,Z22))
K23: =IF(COUNTA(B23:J23)=0,"",SUM(B23:J23)) | L23: =IF(K23="","",B23+C23+G23+H23) | M23: =IF(K23="","",D23+I23) | N23: =IF(K23="","",J23) | O23: =IF(K23="","",E23) | P23: =IF(OR(K23="",K22=""),"",K23-K22) | Q23: =IF(OR(K23="",K11=""),"",K23-K11) | R23: =IFERROR(IF(OR(P23="",K22=0),"",P23/K22),"") | S23: =IF(A23="","",DATEDIF(Inputs!$B$4,A23,"Y")) | Z23: =IF(COUNTA(T23:Y23)=0,"",T23*Inputs!$B$27+U23*Inputs!$B$28+V23*Inputs!$B$29+W23*Inputs!$B$30+X23*Inputs!$B$31+Y23*Inputs!$B$32) | AA23: =IF(K23="","",K23+IF(Z23="",0,Z23))
K24: =IF(COUNTA(B24:J24)=0,"",SUM(B24:J24)) | L24: =IF(K24="","",B24+C24+G24+H24) | M24: =IF(K24="","",D24+I24) | N24: =IF(K24="","",J24) | O24: =IF(K24="","",E24) | P24: =IF(OR(K24="",K23=""),"",K24-K23) | Q24: =IF(OR(K24="",K12=""),"",K24-K12) | R24: =IFERROR(IF(OR(P24="",K23=0),"",P24/K23),"") | S24: =IF(A24="","",DATEDIF(Inputs!$B$4,A24,"Y")) | Z24: =IF(COUNTA(T24:Y24)=0,"",T24*Inputs!$B$27+U24*Inputs!$B$28+V24*Inputs!$B$29+W24*Inputs!$B$30+X24*Inputs!$B$31+Y24*Inputs!$B$32) | AA24: =IF(K24="","",K24+IF(Z24="",0,Z24))
K25: =IF(COUNTA(B25:J25)=0,"",SUM(B25:J25)) | L25: =IF(K25="","",B25+C25+G25+H25) | M25: =IF(K25="","",D25+I25) | N25: =IF(K25="","",J25) | O25: =IF(K25="","",E25) | P25: =IF(OR(K25="",K24=""),"",K25-K24) | Q25: =IF(OR(K25="",K13=""),"",K25-K13) | R25: =IFERROR(IF(OR(P25="",K24=0),"",P25/K24),"") | S25: =IF(A25="","",DATEDIF(Inputs!$B$4,A25,"Y")) | Z25: =IF(COUNTA(T25:Y25)=0,"",T25*Inputs!$B$27+U25*Inputs!$B$28+V25*Inputs!$B$29+W25*Inputs!$B$30+X25*Inputs!$B$31+Y25*Inputs!$B$32) | AA25: =IF(K25="","",K25+IF(Z25="",0,Z25))
K26: =IF(COUNTA(B26:J26)=0,"",SUM(B26:J26)) | L26: =IF(K26="","",B26+C26+G26+H26) | M26: =IF(K26="","",D26+I26) | N26: =IF(K26="","",J26) | O26: =IF(K26="","",E26) | P26: =IF(OR(K26="",K25=""),"",K26-K25) | Q26: =IF(OR(K26="",K14=""),"",K26-K14) | R26: =IFERROR(IF(OR(P26="",K25=0),"",P26/K25),"") | S26: =IF(A26="","",DATEDIF(Inputs!$B$4,A26,"Y")) | Z26: =IF(COUNTA(T26:Y26)=0,"",T26*Inputs!$B$27+U26*Inputs!$B$28+V26*Inputs!$B$29+W26*Inputs!$B$30+X26*Inputs!$B$31+Y26*Inputs!$B$32) | AA26: =IF(K26="","",K26+IF(Z26="",0,Z26))
K27: =IF(COUNTA(B27:J27)=0,"",SUM(B27:J27)) | L27: =IF(K27="","",B27+C27+G27+H27) | M27: =IF(K27="","",D27+I27) | N27: =IF(K27="","",J27) | O27: =IF(K27="","",E27) | P27: =IF(OR(K27="",K26=""),"",K27-K26) | Q27: =IF(OR(K27="",K15=""),"",K27-K15) | R27: =IFERROR(IF(OR(P27="",K26=0),"",P27/K26),"") | S27: =IF(A27="","",DATEDIF(Inputs!$B$4,A27,"Y")) | Z27: =IF(COUNTA(T27:Y27)=0,"",T27*Inputs!$B$27+U27*Inputs!$B$28+V27*Inputs!$B$29+W27*Inputs!$B$30+X27*Inputs!$B$31+Y27*Inputs!$B$32) | AA27: =IF(K27="","",K27+IF(Z27="",0,Z27))
K28: =IF(COUNTA(B28:J28)=0,"",SUM(B28:J28)) | L28: =IF(K28="","",B28+C28+G28+H28) | M28: =IF(K28="","",D28+I28) | N28: =IF(K28="","",J28) | O28: =IF(K28="","",E28) | P28: =IF(OR(K28="",K27=""),"",K28-K27) | Q28: =IF(OR(K28="",K16=""),"",K28-K16) | R28: =IFERROR(IF(OR(P28="",K27=0),"",P28/K27),"") | S28: =IF(A28="","",DATEDIF(Inputs!$B$4,A28,"Y")) | Z28: =IF(COUNTA(T28:Y28)=0,"",T28*Inputs!$B$27+U28*Inputs!$B$28+V28*Inputs!$B$29+W28*Inputs!$B$30+X28*Inputs!$B$31+Y28*Inputs!$B$32) | AA28: =IF(K28="","",K28+IF(Z28="",0,Z28))

Sheet Net Worth
A1: Net Worth & Allocation Dashboard | $ actual
A3: LATEST SNAPSHOT
A4: As-of Date | B4: {=LOOKUP(2,1/('Monthly Balances'!A4:A28<>""),'Monthly Balances'!A4:A28)} -> 45809
A5: Age | B5: =DATEDIF(Inputs!B4,B4,"Y") -> 37
A6: Total Liquid | B6: {=LOOKUP(2,1/('Monthly Balances'!K4:K28<>""),'Monthly Balances'!K4:K28)} -> 266781.17
A7: Property Equity | B7: {=LOOKUP(2,1/('Monthly Balances'!Z4:Z28<>""),'Monthly Balances'!Z4:Z28)} -> 600000
A8: Net Worth | B8: =B6+B7 -> 866781.17
A10: BY TAX BUCKET (Liquid)
A11: Bucket | B11: Balance | C11: % of Liquid | D11: Monthly @ SWR
A12: Cash | B12: {=LOOKUP(2,1/('Monthly Balances'!O4:O28<>""),'Monthly Balances'!O4:O28)} -> 57050.7 | C12: =IFERROR(B12/$B$17,0) -> 0.2138483 | D12: =B12*Inputs!$B$14/12 -> 190.169
A13: Brokerage (taxable) | B13: {=LOOKUP(2,1/('Monthly Balances'!L4:L28<>""),'Monthly Balances'!L4:L28)} -> 10510.53 | C13: =IFERROR(B13/$B$17,0) -> 0.039397571 | D13: =B13*Inputs!$B$14/12 -> 35.0351
A14: Pre-Tax (401K + IRA) | B14: {=LOOKUP(2,1/('Monthly Balances'!M4:M28<>""),'Monthly Balances'!M4:M28)} -> 196969.94 | C14: =IFERROR(B14/$B$17,0) -> 0.73832025 | D14: =B14*Inputs!$B$14/12 -> 656.56647
A15: Roth IRA | B15: {=LOOKUP(2,1/('Monthly Balances'!N4:N28<>""),'Monthly Balances'!N4:N28)} -> 2250 | C15: =IFERROR(B15/$B$17,0) -> 0.0084338786 | D15: =B15*Inputs!$B$14/12 -> 7.5
A16: Other | B16: {=LOOKUP(2,1/(('Monthly Balances'!A4:A28<>"")*('Monthly Balances'!F4:F28<>"")),'Monthly Balances'!F4:F28)} -> 0 | C16: =IFERROR(B16/$B$17,0) -> 0 | D16: =B16*Inputs!$B$14/12 -> 0
A17: Total Liquid | B17: =SUM(B12:B16) -> 266781.17 | C17: =SUM(C12:C16) -> 1 | D17: =SUM(D12:D16) -> 889.27057
A19: ACCOUNT DETAIL (Latest)
A20: Account | B20: Balance | C20: Tax Type
A21: Brokerage_01 | B21: {=LOOKUP(2,1/('Monthly Balances'!B4:B28<>""),'Monthly Balances'!B4:B28)} -> 4374.71 | C21: Brokerage
A22: Brokerage_02 | B22: {=LOOKUP(2,1/('Monthly Balances'!C4:C28<>""),'Monthly Balances'!C4:C28)} -> 2563.7 | C22: Brokerage
A23: 401K | B23: {=LOOKUP(2,1/('Monthly Balances'!D4:D28<>""),'Monthly Balances'!D4:D28)} -> 193969.94 | C23: Traditional 401k
A24: Cash | B24: {=LOOKUP(2,1/('Monthly Balances'!E4:E28<>""),'Monthly Balances'!E4:E28)} -> 57050.7 | C24: Cash
A25: Other | B25: {=LOOKUP(2,1/('Monthly Balances'!F4:F28<>""),'Monthly Balances'!F4:F28)} -> 0 | C25: Other
A26: Brokerage_03 | B26: {=LOOKUP(2,1/('Monthly Balances'!G4:G28<>""),'Monthly Balances'!G4:G28)} -> 1772.12 | C26: Brokerage
A27: Brokerage_04 | B27: {=LOOKUP(2,1/('Monthly Balances'!H4:H28<>""),'Monthly Balances'!H4:H28)} -> 1800 | C27: Brokerage
A28: IRA | B28: {=LOOKUP(2,1/('Monthly Balances'!I4:I28<>""),'Monthly Balances'!I4:I28)} -> 3000 | C28: Traditional IRA
A29: Roth_IRA | B29: {=LOOKUP(2,1/('Monthly Balances'!J4:J28<>""),'Monthly Balances'!J4:J28)} -> 2250 | C29: Roth IRA
A31: TREND (from Monthly Balances)
A32: MoM Liquid Δ | B32: {=LOOKUP(2,1/('Monthly Balances'!P4:P28<>""),'Monthly Balances'!P4:P28)} -> 2075.37
A33: YoY Liquid Δ | B33: {=LOOKUP(2,1/('Monthly Balances'!Q4:Q28<>""),'Monthly Balances'!Q4:Q28)} -> #N/A
A34: MoM % | B34: {=LOOKUP(2,1/('Monthly Balances'!R4:R28<>""),'Monthly Balances'!R4:R28)} -> 0.0078402891

Sheet Retirement Gap
A1: Retirement Gap & Target Income | $ actual
A3: CURRENT PORTFOLIO vs TARGET
A4: Account / Bucket | B4: Current | C4: Target | D4: Gap (Current−Target) | E4: Monthly @ SWR | F4: Target Monthly @ SWR
A5: Brokerage_01 | B5: ='Net Worth'!B21 -> 4374.71 | C5: =Inputs!B18 -> 1500000 | D5: =B5-C5 -> -1495625.3 | E5: =B5*Inputs!$B$14/12 -> 14.582367 | F5: =C5*Inputs!$B$14/12 -> 5000
A6: Brokerage_02 | B6: ='Net Worth'!B22 -> 2563.7 | C6: =Inputs!B19 -> 0 | D6: =B6-C6 -> 2563.7 | E6: =B6*Inputs!$B$14/12 -> 8.5456667 | F6: =C6*Inputs!$B$14/12 -> 0
A7: 401K | B7: ='Net Worth'!B23 -> 193969.94 | C7: =Inputs!B20 -> 1000000 | D7: =B7-C7 -> -806030.06 | E7: =B7*Inputs!$B$14/12 -> 646.56647 | F7: =C7*Inputs!$B$14/12 -> 3333.3333
A8: Brokerage_03 | B8: ='Net Worth'!B26+'Net Worth'!B27 -> 3572.12 | C8: =Inputs!B21 -> 0 | D8: =B8-C8 -> 3572.12 | E8: =B8*Inputs!$B$14/12 -> 11.907067 | F8: =C8*Inputs!$B$14/12 -> 0
A9: IRA | B9: ='Net Worth'!B28 -> 3000 | C9: =Inputs!B22 -> 0 | D9: =B9-C9 -> 3000 | E9: =B9*Inputs!$B$14/12 -> 10 | F9: =C9*Inputs!$B$14/12 -> 0
A10: Roth_IRA | B10: ='Net Worth'!B29 -> 2250 | C10: =Inputs!B23 -> 0 | D10: =B10-C10 -> 2250 | E10: =B10*Inputs!$B$14/12 -> 7.5 | F10: =C10*Inputs!$B$14/12 -> 0
A11: Investable Total | B11: =SUM(B5:B10) -> 209730.47 | C11: =SUM(C5:C10) -> 2500000 | D11: =B11-C11 -> -2290269.5 | E11: =SUM(E5:E10) -> 699.10157 | F11: =SUM(F5:F10) -> 8333.3333
A13: TARGET MONTHLY INCOME BUILD
A14: Component | B14: Current Path | C14: At Target Balances
A15: Portfolio SWR (investable) | B15: =E11 -> 699.10157 | C15: =F11 -> 8333.3333
A16: Social Security (couple) | B16: ='SS Benefits'!B13 -> 4938 | C16: =B16 -> 4938
A17: Rent / Property Income | B17: =Inputs!B15 -> 0 | C17: =B17 -> 0
A18: Total Monthly Income | B18: =B15+B16+B17 -> 5637.1016 | C18: =C15+C16+C17 -> 13271.333
A20: PROJECTED VALUE AT RETIREMENT AGE
A21: Years to Retirement | B21: =MAX(0,Inputs!B8-Inputs!B5) -> 27
A22: Growth Rate | B22: =Inputs!B13 -> 0.06
A23: Inflation | B23: =Inputs!B12 -> 0.03
A24: Brokerage_01 | B24: =B5*(1+Inputs!$B$13)^$B$21 -> 21096.365
A25: Brokerage_02 | B25: =B6*(1+Inputs!$B$13)^$B$21 -> 12363.048
A26: 401K | B26: =B7*(1+Inputs!$B$13)^$B$21 -> 935390.15
A27: Brokerage_03 | B27: =B8*(1+Inputs!$B$13)^$B$21 -> 17225.998
A28: IRA | B28: =B9*(1+Inputs!$B$13)^$B$21 -> 14467.038
A29: Roth | B29: =B10*(1+Inputs!$B$13)^$B$21 -> 10850.278
A30: Total Investable | B30: =SUM(B24:B29) -> 1011392.9
A31: Monthly SWR | B31: =B30*Inputs!$B$14/12 -> 3371.3096
A32: SS + Rent (accounting for inflation) | B32: =B31+'SS Benefits'!B13*(1+Inputs!$B$12)^$B$21+Inputs!B15*(1+Inputs!$B$12)^$B$21 -> 14340.035
A33: Total Monthly (in Today's $) | B33: =B32/(1+Inputs!$B$12)^$B$21 -> 6455.7267
A35: GAP SUMMARY
A36: Investable gap to target | B36: =D11 -> -2290269.5
A37: Years of savings if filling gap evenly | B37: =IFERROR(ABS(D11)/ABS(D11)*$B$21,$B$21) -> 27
A38: Annual savings to close gap (no growth) | B38: =IF($B$21<=0,MAX(0,-D11),MAX(0,-D11)/$B$21) -> 84824.797
A39: Annual savings to close gap (w/ growth) | B39: =IF(OR($B$21<=0,Inputs!$B$13=0),B38,MAX(0,(-D11)*Inputs!$B$13/((1+Inputs!$B$13)^$B$21-1))) -> 35950.742
A41: Notes: Gap negative = below target. SWR portfolio excludes Cash buffer, JLB Other, and Property equity (rent handled separately). Growth projection is balances only — no future contributions unless you add savings in B39.

Sheet SS Benefits
A1: Social Security Claim-Age Table | $ actual / monthly
A3: PRIMARY BENEFITS (edit blue)
A4: Claim Age | B4: Primary SS $/mo | C4: Spouse @ 50% | D4: Couple Monthly | E4: Couple Annual | F4: Years to Age | G4: Cumulative to 70 | H4: Cumulative to 75 | I4: Cumulative to 80 | J4: Cumulative to 85
A5: 62 | B5: 2568 | C5: =B5*0.5 -> 1284 | D5: =B5+C5 -> 3852 | E5: =D5*12 -> 46224 | F5: =A5-Inputs!$B$5 -> 24 | G5: =MAX(0,70-A5)*B5*12 -> 246528 | H5: =MAX(0,75-A5)*B5*12 -> 400608 | I5: =MAX(0,80-A5)*B5*12 -> 554688 | J5: =MAX(0,85-A5)*B5*12 -> 708768
A6: 65 | B6: 3292 | C6: =B6*0.5 -> 1646 | D6: =B6+C6 -> 4938 | E6: =D6*12 -> 59256 | F6: =A6-Inputs!$B$5 -> 27 | G6: =MAX(0,70-A6)*B6*12 -> 197520 | H6: =MAX(0,75-A6)*B6*12 -> 395040 | I6: =MAX(0,80-A6)*B6*12 -> 592560 | J6: =MAX(0,85-A6)*B6*12 -> 790080
A7: 67 | B7: 3899 | C7: =B7*0.5 -> 1949.5 | D7: =B7+C7 -> 5848.5 | E7: =D7*12 -> 70182 | F7: =A7-Inputs!$B$5 -> 29 | G7: =MAX(0,70-A7)*B7*12 -> 140364 | H7: =MAX(0,75-A7)*B7*12 -> 374304 | I7: =MAX(0,80-A7)*B7*12 -> 608244 | J7: =MAX(0,85-A7)*B7*12 -> 842184
A8: 70 | B8: 4965 | C8: =B8*0.5 -> 2482.5 | D8: =B8+C8 -> 7447.5 | E8: =D8*12 -> 89370 | F8: =A8-Inputs!$B$5 -> 32 | G8: =MAX(0,70-A8)*B8*12 -> 0 | H8: =MAX(0,75-A8)*B8*12 -> 297900 | I8: =MAX(0,80-A8)*B8*12 -> 595800 | J8: =MAX(0,85-A8)*B8*12 -> 893700
A10: SELECTED CLAIM SCENARIO
A11: Planned Claim Age | B11: =Inputs!B8 -> 65
A12: Primary SS at Claim | B12: =_xlfn.XLOOKUP(B11,A5:A8,B5:B8) -> 3292
A13: Couple Monthly (Primary+50%) | B13: =_xlfn.XLOOKUP(B11,A5:A8,D5:D8) -> 4938
A14: Note | B14: Spouse 50% is a simplified placeholder — replace with actual spousal benefit when known.

Sheet IRMAA
A1: IRMAA Module (Placeholder) — Medicare Income-Related Monthly Adjustment Amount
A3: PURPOSE
A4: Track MAGI vs IRMAA brackets so withdrawals and Roth conversions stay under cliffs. Populate brackets annually; wire MAGI from Tax + What-If sheets.
A6: INPUTS
A7: Tax Year | B7: 2026
A8: Filing Status | B8: =Inputs!B6 -> Married Filing Jointly
A9: Projected MAGI | B9: =100000+B11 -> 100000
A10: of which: SS taxable | B10: =Tax!F14 -> 50367.6
A11: of which: Roth conversions | B11: ='Roth Conversion'!B9 -> 0
A12: of which: 401k/IRA withdrawals | B12: =Tax!F5 -> 0
A14: 2026 IRMAA BRACKETS — MFJ (2024 MAGI; monthly surcharge per person)
A15: Tier | B15: MAGI From | C15: MAGI To | D15: Part B IRMAA/mo | E15: Part D IRMAA/mo
A16: 0 | B16: 0 | C16: 218000 | D16: 0 | E16: 0
A17: 1 | B17: 218001 | C17: 274000 | D17: 81.2 | E17: 14.5
A18: 2 | B18: 274001 | C18: 342000 | D18: 202.9 | E18: 37.5
A19: 3 | B19: 342001 | C19: 410000 | D19: 324.6 | E19: 60.4
A20: 4 | B20: 410001 | C20: 749999 | D20: 446.3 | E20: 83.3
A21: 5 | B21: 750000 | C21: No limit | D21: 487 | E21: 91
A22: APP HOOKS
A23: • get IRMAA Tier (magi, filing status, year)
A24: • headroom to next cliff (magi)
A25: • max conversion before cliff (magi)
A26: Status | B26: 2026 OFFICIAL — update annually
A28: Live years in IRMAA | B28: =Timeline!D46 -> 0
A29: Cliff input | B29: =Timeline!BB8 -> 218000

Sheet RMD
A1: RMD — Required Minimum Distributions
A3: PURPOSE
A4: Compute RMDs on pre-tax accounts (401k, Trad IRA) using Uniform Lifetime Table; feed Tax and withdrawal optimizer.
A6: PROFILE LINKS
A7: DOB | B7: =Inputs!B4 -> 32143
A8: Current Age | B8: =Inputs!B5 -> 38
A9: RMD Start Age (SECURE 2.0) | B9: =IF(YEAR(B7)>=1960,75,IF(YEAR(B7)>=1951,73,IF(YEAR(B7)>=1949,72,70.5))) -> 75
A10: Years Until RMD | B10: =MAX(0,B9-B8) -> 37
A11: RMD Applies Now? | B11: =IF(B8>=B9,"Yes","No") -> No
A12: Factor at RMD Start Age | B12: =_xlfn.XLOOKUP(B9,$A$21:$A$69,$B$21:$B$69,"") -> 24.6
A13: PRE-TAX BALANCES (latest)
A14: Account | B14: Balance | C14: Prior Year-End (for RMD) | D14: Life Expectancy Factor | E14: RMD Amount
A15: 401K | B15: ='Net Worth'!B23 -> 193969.94 | C15: 0 | D15: =IF($B$11="No",0,_xlfn.XLOOKUP($B$8,$A$21:$A$69,$B$21:$B$69,0)) -> 0 | E15: =IF(OR($B$11="No",D15=0),0,C15/D15) -> 0
A16: IRA | B16: ='Net Worth'!B28 -> 3000 | C16: 0 | D16: =IF($B$11="No",0,_xlfn.XLOOKUP($B$8,$A$21:$A$69,$B$21:$B$69,0)) -> 0 | E16: =IF(OR($B$11="No",D16=0),0,C16/D16) -> 0
A17: Total RMD | E17: =SUM(E15:E16) -> 0
A19: UNIFORM LIFETIME TABLE — IRS TABLE III (current factors)
A20: Age | B20: Factor
A21: 72 | B21: 27.4
A22: 73 | B22: 26.5
A23: 74 | B23: 25.5
A24: 75 | B24: 24.6
A25: 76 | B25: 23.7
A26: 77 | B26: 22.9
A27: 78 | B27: 22
A28: 79 | B28: 21.1
A29: 80 | B29: 20.2
A30: 81 | B30: 19.4
A31: 82 | B31: 18.5
A32: 83 | B32: 17.7
... A69: 120 | B69: 2
A71: APP HOOKS
A72: • RMD Amount (balance Prior YE, age, table)
A73: • years To RMD (dob, rmd Start Age)
A74: • pre Tax Balance Projection (contrib, return, years) for RMD pressure
A75: Status | B75: =IF(B11="Yes","RMD required — use prior year-end balances","RMD not required yet; first RMD year is "&(YEAR(B7)+B9)) -> RMD not required yet; first RMD year is 2063
A77: Live RMD path
A78: Timeline row RMD_Required. Pre-tax drains via conversions.
A79: Ending pre-tax | B79: =Timeline!D44 -> 1941186.1

Sheet Roth Conversion
A1: Roth Conversion Optimizer (Placeholder)
A3: PURPOSE
A4: Model annual conversions from 401k/Trad IRA → Roth IRA within tax bracket and IRMAA headroom; minimize lifetime tax + RMD.
A6: SOURCE / DESTINATION
A7: Pre-Tax Available | B7: ='Net Worth'!B23+'Net Worth'!B28 -> 196969.94
A8: Current Roth Balance | B8: ='Net Worth'!B29 -> 2250
A9: Planned Conversion (this year) | B9: 0
A10: Federal Bracket Cap (taxable income room) | B10: =MAX(0,Tax!B12+Tax!F16-(Tax!F11-Tax!F6)-Tax!F9*85%) -> 0
A11: IRMAA Headroom | B11: =MAX(0,IRMAA!C16-(IRMAA!B9-IRMAA!B11)) -> 118000
A12: Max Conversion (min of constraints) | B12: =MAX(0,MIN(B7,B10,B11)) -> 0
A13: Conversion within cap? | B13: =IF(B9<=B12,"OK","EXCEEDS") -> OK
A15: MULTI-YEAR PLAN (inputs)
A16: Year | B16: Conversion $ | C16: Est. Tax @ 12% | D16: Ending Pre-Tax | E16: Ending Roth
A17: 1 | B17: =$B$9 -> 0 | C17: =B17*12% -> 0 | D17: =$B$7-B17 -> 196969.94 | E17: =$B$8+B17 -> 2250
A18: 2 | B18: =MIN($B$10,D17) -> 0 | C18: =B18*12% -> 0 | D18: =D17-B18 -> 196969.94 | E18: =E17+B18 -> 2250
A19: 3 | B19: =MIN($B$10,D18) -> 0 | C19: =B19*12% -> 0 | D19: =D18-B19 -> 196969.94 | E19: =E18+B19 -> 2250
A20: 4 | B20: =MIN($B$10,D19) -> 0 | C20: =B20*12% -> 0 | D20: =D19-B20 -> 196969.94 | E20: =E19+B20 -> 2250
A21: 5 | B21: =MIN($B$10,D20) -> 0 | C21: =B21*12% -> 0 | D21: =D20-B21 -> 196969.94 | E21: =E20+B21 -> 2250
A23: APP HOOKS
A24: • optimalConversion(bracketRoom, irmaaRoom, preTaxBal, yearsToRMD)
A25: • lifetimeTaxWithVsWithoutConversion(...)
A26: Status | B26: ILLUSTRATIVE — Tax + IRMAA linked; edit Timeline for live plan
A28: Live plan
A29: Total planned conversions | B29: =Timeline!D42 -> 0
A30: Edit yearly amounts on Timeline Roth_Conversion (yellow)

Sheet Tax
A1: Tax Engine — Brackets by Filing Status & Tax Year | 2025-2026 IRS; later inflation-indexed to horizon | AC1: YEAR LIST
AC2: StartYear | AD2: 2025
A3: FILING STATUS (from Inputs) | E3: ANNUAL TAX CALCULATOR | AC3: EndYear | AD3: =YEAR(Inputs!B4)+Inputs!B9 -> 2073
A4: Active filing status | B4: =Inputs!B6 -> Married Filing Jointly | E4: Wages / other ordinary | F4: 186240 | AC4: Inflation | AD4: =Inputs!B12 -> 0.03
A5: Tax year | B5: 2026 | C5: Ends at Inputs horizon (DOB year + B9). 2025-2026 = IRS; later = inflate from 2026. | E5: 401k/IRA withdrawals | F5: 0 | AC5: Count | AD5: =AD3-AD2+1 -> 49
A6: First tax year (list start) | B6: =YEAR(TODAY()) -> 2026 | E6: Roth conversions | F6: ='Roth Conversion'!B9 -> 0
A7: ACTIVE PARAMETERS (filing status x tax year) | E7: Taxable interest / non-QD | F7: 0
A8: Param source | B8: =IF(B5<=2025,"2025 IRS",IF(B5=2026,"2026 IRS","2026+inflate")) -> 2026 IRS | E8: Qualified div + LTCG | F8: 0 | AC8: TaxYearList
E9: Social Security (gross) | F9: ='SS Benefits'!B13*12 -> 59256 | AC9: =IF(AD2+0>$AD$3,"",AD2+0) -> 2025
A10: Standard deduction | B10: =IF($B$5<=2025,_xlfn.XLOOKUP($B$4,$A$41:$A$45,B41:B45),ROUND(_xlfn.XLOOKUP($B$4,$A$51:$A$55,B51:B55)*(1+$AD$4)^MAX(0,$B$5-2026),0)) -> 32200 | AC10: =IF(AD2+1>$AD$3,"",AD2+1) -> 2026
A11: Ordinary 10% top | B11: =IF($B$5<=2025,_xlfn.XLOOKUP($B$4,$A$41:$A$45,C41:C45),ROUND(_xlfn.XLOOKUP($B$4,$A$51:$A$55,C51:C55)*(1+$AD$4)^MAX(0,$B$5-2026),0)) -> 24800 | E11: Ordinary excl. SS | F11: =F4+F5+F6+F7 -> 186240 | AC11: =IF(AD2+2>$AD$3,"",AD2+2) -> 2027
A12: Ordinary 12% top | B12: =IF($B$5<=2025,_xlfn.XLOOKUP($B$4,$A$41:$A$45,D41:D45),ROUND(_xlfn.XLOOKUP($B$4,$A$51:$A$55,D51:D55)*(1+$AD$4)^MAX(0,$B$5-2026),0)) -> 100800 | E12: Provisional income | F12: =F11+F8+F9*0.5 -> 215868 | AC12: =IF(AD2+3>$AD$3,"",AD2+3) -> 2028
A13: Ordinary 22% top | B13: =IF($B$5<=2025,_xlfn.XLOOKUP($B$4,$A$41:$A$45,E41:E45),ROUND(_xlfn.XLOOKUP($B$4,$A$51:$A$55,E51:E55)*(1+$AD$4)^MAX(0,$B$5-2026),0)) -> 211400 | E13: Taxable SS % | F13: =IF(AND(B21<=0,B22<=0),IF(F9>0,0.85,0),IF(F12<B21,0,IF(F12<B22,0.5,0.85))) -> 0.85 | AC13: =IF(AD2+4>$AD$3,"",AD2+4) -> 2029
A14: Ordinary 24% top | B14: =IF($B$5<=2025,_xlfn.XLOOKUP($B$4,$A$41:$A$45,F41:F45),ROUND(_xlfn.XLOOKUP($B$4,$A$51:$A$55,F51:F55)*(1+$AD$4)^MAX(0,$B$5-2026),0)) -> 403550 | E14: Taxable SS $ | F14: =F9*F13 -> 50367.6 | AC14: =IF(AD2+5>$AD$3,"",AD2+5) -> 2030
A15: Ordinary 32% top | B15: =IF($B$5<=2025,_xlfn.XLOOKUP($B$4,$A$41:$A$45,G41:G45),ROUND(_xlfn.XLOOKUP($B$4,$A$51:$A$55,G51:G55)*(1+$AD$4)^MAX(0,$B$5-2026),0)) -> 512450 | E15: Total ordinary (incl tax SS) | F15: =F11+F14 -> 236607.6 | AC15: =IF(AD2+6>$AD$3,"",AD2+6) -> 2031
A16: Ordinary 35% top | B16: =IF($B$5<=2025,_xlfn.XLOOKUP($B$4,$A$41:$A$45,H41:H45),ROUND(_xlfn.XLOOKUP($B$4,$A$51:$A$55,H51:H55)*(1+$AD$4)^MAX(0,$B$5-2026),0)) -> 768700 | E16: Std deduction (status) | F16: =B10 -> 32200 | AC16: =IF(AD2+7>$AD$3,"",AD2+7) -> 2032
A17: Ordinary 37% starts above | B17: =B16 -> 768700 | E17: Taxable ordinary | F17: =MAX(0,F15-F16) -> 204407.6 | AC17: =IF(AD2+8>$AD$3,"",AD2+8) -> 2033
A18: LTCG 0% top (taxable income) | B18: =IF($B$5<=2025,_xlfn.XLOOKUP($B$4,$A$41:$A$45,I41:I45),ROUND(_xlfn.XLOOKUP($B$4,$A$51:$A$55,I51:I55)*(1+$AD$4)^MAX(0,$B$5-2026),0)) -> 98900 | E18: LTCG / QD | F18: =F8 -> 0 | AC18: =IF(AD2+9>$AD$3,"",AD2+9) -> 2034
A19: LTCG 15% top / 20% starts above (taxable income) | B19: =IF($B$5<=2025,_xlfn.XLOOKUP($B$4,$A$41:$A$45,J41:J45),ROUND(_xlfn.XLOOKUP($B$4,$A$51:$A$55,J51:J55)*(1+$AD$4)^MAX(0,$B$5-2026),0)) -> 613700 | AC19: =IF(AD2+10>$AD$3,"",AD2+10) -> 2035
A20: NIIT MAGI threshold | B20: =IF($B$5<=2025,_xlfn.XLOOKUP($B$4,$A$41:$A$45,K41:K45),_xlfn.XLOOKUP($B$4,$A$51:$A$55,K51:K55)) -> 250000 | E20: Ordinary tax | F20: =_xlfn.LET(_xlpm.t,F17,MAX(0,MIN(_xlpm.t,B11))*0.1+MAX(0,MIN(_xlpm.t,B12)-B11)*0.12+MAX(0,MIN(_xlpm.t,B13)-B12)*0.22+MAX(0,MIN(_xlpm.t,B14)-B13)*0.24+MAX(0,MIN(_xlpm.t,B15)-B14)*0.32+MAX(0,MIN(_xlpm.t,B16)-B15)*0.35+MAX(0,_xlpm.t-B16)*0.37) -> 34393.672 | AC20: =IF(AD2+11>$AD$3,"",AD2+11) -> 2036
A21: SS provisional base (0 to 50%) | B21: =IF($B$5<=2025,_xlfn.XLOOKUP($B$4,$A$41:$A$45,L41:L45),_xlfn.XLOOKUP($B$4,$A$51:$A$55,L51:L55)) -> 32000 | E21: LTCG tax (stacked) | F21: =_xlfn.LET(_xlpm.lo,F17,_xlpm.hi,F17+F18,MAX(0,MIN(_xlpm.hi,B18)-_xlpm.lo)*0+MAX(0,MIN(_xlpm.hi,B19)-MAX(_xlpm.lo,B18))*0.15+MAX(0,_xlpm.hi-MAX(_xlpm.lo,B19))*0.2) -> 0 | AC21: =IF(AD2+12>$AD$3,"",AD2+12) -> 2037
A22: SS provisional base (50 to 85%) | B22: =IF($B$5<=2025,_xlfn.XLOOKUP($B$4,$A$41:$A$45,M41:M45),_xlfn.XLOOKUP($B$4,$A$51:$A$55,M51:M55)) -> 44000 | E22: NIIT 3.8% | F22: =MAX(0,(F15+F18)-B20)*0.038 -> 0 | AC22: =IF(AD2+13>$AD$3,"",AD2+13) -> 2038
E23: Total federal tax | F23: =F20+F21+F22 -> 34393.672 | AC23: =IF(AD2+14>$AD$3,"",AD2+14) -> 2039
A24: ACTIVE ORDINARY BRACKETS | E24: Effective rate | F24: =IFERROR(F23/MAX(1,F15+F18+(F9-F14)),0) -> 0.14009871 | AC24: =IF(AD2+15>$AD$3,"",AD2+15) -> 2040
A25: Rate | B25: Taxable income from | C25: Taxable income to | AC25: =IF(AD2+16>$AD$3,"",AD2+16) -> 2041
A26: 0.1 | B26: 0 | C26: =B11 -> 24800 | E26: LINKED TO TIMELINE | AC26: =IF(AD2+17>$AD$3,"",AD2+17) -> 2042
A27: 0.12 | B27: =B11 -> 24800 | C27: =B12 -> 100800 | E27: StdDed, ord tops, LTCG, NIIT, SS bases → Timeline AI cells | AC27: =IF(AD2+18>$AD$3,"",AD2+18) -> 2043
A28: 0.22 | B28: =B12 -> 100800 | C28: =B13 -> 211400 | E28: Live lifetime tax (Timeline) | F28: =Timeline!D41 -> 693787.14 | AC28: =IF(AD2+19>$AD$3,"",AD2+19) -> 2044
A29: 0.24 | B29: =B13 -> 211400 | C29: =B14 -> 403550 | AC29: =IF(AD2+20>$AD$3,"",AD2+20) -> 2045
A30: 0.32 | B30: =B14 -> 403550 | C30: =B15 -> 512450 | AC30: =IF(AD2+21>$AD$3,"",AD2+21) -> 2046
A31: 0.35 | B31: =B15 -> 512450 | C31: =B16 -> 768700 | AC31: =IF(AD2+22>$AD$3,"",AD2+22) -> 2047
A32: 0.37 | B32: =B16 -> 768700 | C32: No limit | AC32: =IF(AD2+23>$AD$3,"",AD2+23) -> 2048
AC33: =IF(AD2+24>$AD$3,"",AD2+24) -> 2049
A34: SURVIVING SPOUSE / STATUS CHANGE | AC34: =IF(AD2+25>$AD$3,"",AD2+25) -> 2050
A35: Year of death: often still MFJ if eligible. Next FY: Qualifying Surviving Spouse (if rules met) up to 2 years — MFJ-like brackets/std ded. | AC35: =IF(AD2+26>$AD$3,"",AD2+26) -> 2051
A36: After QSS ends: Single or HoH — brackets tighten, std ded drops, NIIT often $200k, SS bases use single thresholds. | AC36: =IF(AD2+27>$AD$3,"",AD2+27) -> 2052
A37: Change Inputs B6 → Tax brackets update → Timeline tax engine reads these parameters. | AC37: =IF(AD2+28>$AD$3,"",AD2+28) -> 2053
AC38: =IF(AD2+29>$AD$3,"",AD2+29) -> 2054
A39: BRACKET TABLE TY2025 (IRS base) | AC39: =IF(AD2+30>$AD$3,"",AD2+30) -> 2055
A40: Filing Status | B40: StdDed | C40: Ord10 | D40: Ord12 | E40: Ord22 | F40: Ord24 | G40: Ord32 | H40: Ord35 | I40: LTCG0 | J40: LTCG15Top / LTCG20Start | K40: NIIT | L40: SS_0to50 | M40: SS_50to85 | AC40: =IF(AD2+31>$AD$3,"",AD2+31) -> 2056
...

Sheet What-If
A1: What-If Withdrawal Scenarios (Placeholder) | AG1: ID | AH1: PreTax Share | AI1: Roth Share | AJ1: Conversion Level | AK1: Brokerage WD | AL1: PreTax WD | AM1: Roth WD | AN1: Conversion | AO1: Federal Tax | AP1: IRMAA Tier | AQ1: Ending Investable | AR1: Ending PreTax | AS1: Feasible | AT1: Score
AG2: =ROW()-1 -> 1 | AH2: =INT((AG2-1)/66)/10 -> 0 | AI2: =MOD(INT((AG2-1)/6),11)/10 -> 0 | AJ2: =MOD(AG2-1,6)/5 -> 0 | AK2: =MAX(0,$B$10-AL2-AM2) -> 60744 | AL2: =MIN($B$10*AH2,$B$47) -> 0 | AM2: =MIN(MAX(0,$B$10-AL2)*AI2,'Retirement Gap'!$B$29) -> 0 | AN2: =IF($E$40="B - Withdrawals + Roth conversions",AJ2*MAX(0,MIN($B$47-AL2,MIN($B$59,IRMAA!$C$16)-(AL2+$B$8*0.85+AK2*$B$46))),0) -> 0 | AO2: {=_xlfn.LET(_xlpm.N,$B$49,_xlpm.R,$B$48,_xlpm.Start,$B$47,_xlpm.PlanWD,AL2,_xlpm.PlanRoth,AM2,_xlpm.PlanConv,AN2,_xlpm.Ages,Inputs!$B$8+_xlfn.SEQUENCE(_xlpm.N)-1,_xlpm.Bals,_xlfn.SCAN(_xlpm.Start,_xlfn.SEQUENCE(_xlpm.N),_xlfn.LAMBDA(_xlpm.Open,_xlpm.i,_xlfn.LET(_xlpm.Age,Inputs!$B$8+_xlpm.i-1,_xlpm.Factor,_xlfn.XLOOKUP(_xlpm.Age,RMD!$A$21:$A$69,RMD!$B$21:$B$69,0),_xlpm.Req,IF(AND(_xlpm.Age>=RMD!$B$9,_xlpm.Factor>0),_xlpm.Open/_xlpm.Factor,0),_xlpm.SpendWD,MIN(_xlpm.Open,MAX(_xlpm.PlanWD,_xlpm.Req)),_xlpm.Conv,MIN(MAX(0,_xlpm.Open-_xlpm.SpendWD),_xlpm.PlanConv),MAX(0,_xlpm.Open*(1+_xlpm.R)-_xlpm.SpendWD-_xlpm.Conv)))),_xlpm.Opens,_xlfn.MAP(_xlfn.SEQUENCE(_xlpm.N),_xlfn.LAMBDA(_xlpm.i,IF(_xlpm.i=1,_xlpm.Start,INDEX(_xlpm.Bals,_xlpm.i-1)))),_xlpm.Reqs,_xlfn.MAP(_xlpm.Opens,_xlpm.Ages,_xlfn.LAMBDA(_xlpm.Open,_xlpm.Age,_xlfn.LET(_xlpm.Factor,_xlfn.XLOOKUP(_xlpm.Age,RMD!$A$21:$A$69,RMD!$B$21:$B$69,0),IF(AND(_xlpm.Age>=RMD!$B$9,_xlpm.Factor>0),_xlpm.Open/_xlpm.Factor,0)))),_xlpm.SpendWDs,_xlfn.MAP(_xlpm.Opens,_xlpm.Reqs,_xlfn.LAMBDA(_xlpm.Open,_xlpm.Req,MIN(_xlpm.Open,MAX(_xlpm.PlanWD,_xlpm.Req)))),_xlpm.Convs,_xlfn.MAP(_xlpm.Opens,_xlpm.SpendWDs,_xlfn.LAMBDA(_xlpm.Open,_xlpm.WD,MIN(MAX(0,_xlpm.Open-_xlpm.WD),_xlpm.PlanConv))),_xlpm.BRs,_xlfn.MAP(_xlpm.SpendWDs,_xlfn.LAMBDA(_xlpm.WD,MAX(0,$B$10-_xlpm.WD-_xlpm.PlanRoth))),_xlpm.TAX,_xlfn.LAMBDA(_xlpm.PT,_xlpm.BR,_xlfn.LET(_xlpm.SS,$B$8,_xlpm.CG,_xlpm.BR*$B$46,_xlpm.Prov,_xlpm.PT+_xlpm.CG+_xlpm.SS*0.5,_xlpm.TSS,_xlpm.SS*IF(AND(Tax!$B$21<=0,Tax!$B$22<=0),IF(_xlpm.SS>0,0.85,0),IF(_xlpm.Prov<Tax!$B$21,0,IF(_xlpm.Prov<Tax!$B$22,0.5,0.85))),_xlpm.Ord,_xlpm.PT+_xlpm.TSS,_xlpm.TO,MAX(0,_xlpm.Ord-Tax!$B$10),_xlpm.OT,MAX(0,MIN(_xlpm.TO,Tax!$B$11))*0.1+MAX(0,MIN(_xlpm.TO,Tax!$B$12)-Tax!$B$11)*0.12+MAX(0,MIN(_xlpm.TO,Tax!$B$13)-Tax!$B$12)*0.22+MAX(0,MIN(_xlpm.TO,Tax!$B$14)-Tax!$B$13)*0.24+MAX(0,MIN(_xlpm.TO,Tax!$B$15)-Tax!$B$14)*0.32+MAX(0,MIN(_xlpm.TO,Tax!$B$16)-Tax!$B$15)*0.35+MAX(0,_xlpm.TO-Tax!$B$16)*0.37,_xlpm.HI,_xlpm.TO+_xlpm.CG,_xlpm.CGT,MAX(0,MIN(_xlpm.HI,Tax!$B$18)-_xlpm.TO)*0+MAX(0,MIN(_xlpm.HI,Tax!$B$19)-MAX(_xlpm.TO,Tax!$B$18))*0.15+MAX(0,_xlpm.HI-MAX(_xlpm.TO,Tax!$B$19))*0.2,_xlpm.MAGI,_xlpm.PT+_xlpm.TSS+_xlpm.CG,_xlpm.NIIT,MAX(0,MIN(_xlpm.CG,_xlpm.MAGI-Tax!$B$20))*0.038,_xlpm.OT+_xlpm.CGT+_xlpm.NIIT)),_xlpm.Taxes,_xlfn.MAP(_xlpm.SpendWDs,_xlpm.Convs,_xlpm.BRs,_xlfn.LAMBDA(_xlpm.WD,_xlpm.Conv,_xlpm.BR,_xlpm.TAX(_xlpm.WD+_xlpm.Conv,_xlpm.BR))),SUM(_xlpm.Taxes))} -> 9083.8 | AP2: {=_xlfn.LET(_xlpm.N,$B$49,_xlpm.R,$B$48,_xlpm.Start,$B$47,_xlpm.PlanWD,AL2,_xlpm.PlanRoth,AM2,_xlpm.PlanConv,AN2,_xlpm.Ages,Inputs!$B$8+_xlfn.SEQUENCE(_xlpm.N)-1,_xlpm.Bals,_xlfn.SCAN(_xlpm.Start,_xlfn.SEQUENCE(_xlpm.N),_xlfn.LAMBDA(_xlpm.Open,_xlpm.i,_xlfn.LET(_xlpm.Age,Inputs!$B$8+_xlpm.i-1,_xlpm.Factor,_xlfn.XLOOKUP(_xlpm.Age,RMD!$A$21:$A$69,RMD!$B$21:$B$69,0),_xlpm.Req,IF(AND(_xlpm.Age>=RMD!$B$9,_xlpm.Factor>0),_xlpm.Open/_xlpm.Factor,0),_xlpm.SpendWD,MIN(_xlpm.Open,MAX(_xlpm.PlanWD,_xlpm.Req)),_xlpm.Conv,MIN(MAX(0,_xlpm.Open-_xlpm.SpendWD),_xlpm.PlanConv),MAX(0,_xlpm.Open*(1+_xlpm.R)-_xlpm.SpendWD-_xlpm.Conv)))),_xlpm.Opens,_xlfn.MAP(_xlfn.SEQUENCE(_xlpm.N),_xlfn.LAMBDA(_xlpm.i,IF(_xlpm.i=1,_xlpm.Start,INDEX(_xlpm.Bals,_xlpm.i-1)))),_xlpm.Reqs,_xlfn.MAP(_xlpm.Opens,_xlpm.Ages,_xlfn.LAMBDA(_xlpm.Open,_xlpm.Age,_xlfn.LET(_xlpm.Factor,_xlfn.XLOOKUP(_xlpm.Age,RMD!$A$21:$A$69,RMD!$B$21:$B$69,0),IF(AND(_xlpm.Age>=RMD!$B$9,_xlpm.Factor>0),_xlpm.Open/_xlpm.Factor,0)))),_xlpm.SpendWDs,_xlfn.MAP(_xlpm.Opens,_xlpm.Reqs,_xlfn.LAMBDA(_xlpm.Open,_xlpm.Req,MIN(_xlpm.Open,MAX(_xlpm.PlanWD,_xlpm.Req)))),_xlpm.Convs,_xlfn.MAP(_xlpm.Opens,_xlpm.SpendWDs,_xlfn.LAMBDA(_xlpm.Open,_xlpm.WD,MIN(MAX(0,_xlpm.Open-_xlpm.WD),_xlpm.PlanConv))),_xlpm.BRs,_xlfn.MAP(_xlpm.SpendWDs,_xlfn.LAMBDA(_xlpm.WD,MAX(0,$B$10-_xlpm.WD-_xlpm.PlanRoth))),_xlpm.TIER,_xlfn.LAMBDA(_xlpm.PT,_xlpm.BR,_xlfn.LET(_xlpm.SS,$B$8,_xlpm.CG,_xlpm.BR*$B$46,_xlpm.Prov,_xlpm.PT+_xlpm.CG+_xlpm.SS*0.5,_xlpm.TSS,_xlpm.SS*IF(AND(Tax!$B$21<=0,Tax!$B$22<=0),IF(_xlpm.SS>0,0.85,0),IF(_xlpm.Prov<Tax!$B$21,0,IF(_xlpm.Prov<Tax!$B$22,0.5,0.85))),_xlpm.MAGI,_xlpm.PT+_xlpm.TSS+_xlpm.CG,LOOKUP(_xlpm.MAGI,IRMAA!$B$16:$B$21,IRMAA!$A$16:$A$21))),_xlpm.Tiers,_xlfn.MAP(_xlpm.SpendWDs,_xlpm.Convs,_xlpm.BRs,_xlfn.LAMBDA(_xlpm.WD,_xlpm.Conv,_xlpm.BR,_xlpm.TIER(_xlpm.WD+_xlpm.Conv,_xlpm.BR))),MAX(_xlpm.Tiers))} -> 0 | AQ2: {=_xlfn.LET(_xlpm.N,$B$49,_xlpm.R,$B$48,_xlpm.Start,$B$47,_xlpm.PlanWD,AL2,_xlpm.PlanRoth,AM2,_xlpm.PlanConv,AN2,_xlpm.Ages,Inputs!$B$8+_xlfn.SEQUENCE(_xlpm.N)-1,_xlpm.Bals,_xlfn.SCAN(_xlpm.Start,_xlfn.SEQUENCE(_xlpm.N),_xlfn.LAMBDA(_xlpm.Open,_xlpm.i,_xlfn.LET(_xlpm.Age,Inputs!$B$8+_xlpm.i-1,_xlpm.Factor,_xlfn.XLOOKUP(_xlpm.Age,RMD!$A$21:$A$69,RMD!$B$21:$B$69,0),_xlpm.Req,IF(AND(_xlpm.Age>=RMD!$B$9,_xlpm.Factor>0),_xlpm.Open/_xlpm.Factor,0),_xlpm.SpendWD,MIN(_xlpm.Open,MAX(_xlpm.PlanWD,_xlpm.Req)),_xlpm.Conv,MIN(MAX(0,_xlpm.Open-_xlpm.SpendWD),_xlpm.PlanConv),MAX(0,_xlpm.Open*(1+_xlpm.R)-_xlpm.SpendWD-_xlpm.Conv)))),_xlpm.Opens,_xlfn.MAP(_xlfn.SEQUENCE(_xlpm.N),_xlfn.LAMBDA(_xlpm.i,IF(_xlpm.i=1,_xlpm.Start,INDEX(_xlpm.Bals,_xlpm.i-1)))),_xlpm.Reqs,_xlfn.MAP(_xlpm.Opens,_xlpm.Ages,_xlfn.LAMBDA(_xlpm.Open,_xlpm.Age,_xlfn.LET(_xlpm.Factor,_xlfn.XLOOKUP(_xlpm.Age,RMD!$A$21:$A$69,RMD!$B$21:$B$69,0),IF(AND(_xlpm.Age>=RMD!$B$9,_xlpm.Factor>0),_xlpm.Open/_xlpm.Factor,0)))),_xlpm.SpendWDs,_xlfn.MAP(_xlpm.Opens,_xlpm.Reqs,_xlfn.LAMBDA(_xlpm.Open,_xlpm.Req,MIN(_xlpm.Open,MAX(_xlpm.PlanWD,_xlpm.Req)))),_xlpm.Convs,_xlfn.MAP(_xlpm.Opens,_xlpm.SpendWDs,_xlfn.LAMBDA(_xlpm.Open,_xlpm.WD,MIN(MAX(0,_xlpm.Open-_xlpm.WD),_xlpm.PlanConv))),_xlpm.BRs,_xlfn.MAP(_xlpm.SpendWDs,_xlfn.LAMBDA(_xlpm.WD,MAX(0,$B$10-_xlpm.WD-_xlpm.PlanRoth))),_xlpm.TAX,_xlfn.LAMBDA(_xlpm.PT,_xlpm.BR,_xlfn.LET(_xlpm.SS,$B$8,_xlpm.CG,_xlpm.BR*$B$46,_xlpm.Prov,_xlpm.PT+_xlpm.CG+_xlpm.SS*0.5,_xlpm.TSS,_xlpm.SS*IF(AND(Tax!$B$21<=0,Tax!$B$22<=0),IF(_xlpm.SS>0,0.85,0),IF(_xlpm.Prov<Tax!$B$21,0,IF(_xlpm.Prov<Tax!$B$22,0.5,0.85))),_xlpm.Ord,_xlpm.PT+_xlpm.TSS,_xlpm.TO,MAX(0,_xlpm.Ord-Tax!$B$10),_xlpm.OT,MAX(0,MIN(_xlpm.TO,Tax!$B$11))*0.1+MAX(0,MIN(_xlpm.TO,Tax!$B$12)-Tax!$B$11)*0.12+MAX(0,MIN(_xlpm.TO,Tax!$B$13)-Tax!$B$12)*0.22+MAX(0,MIN(_xlpm.TO,Tax!$B$14)-Tax!$B$13)*0.24+MAX(0,MIN(_xlpm.TO,Tax!$B$15)-Tax!$B$14)*0.32+MAX(0,MIN(_xlpm.TO,Tax!$B$16)-Tax!$B$15)*0.35+MAX(0,_xlpm.TO-Tax!$B$16)*0.37,_xlpm.HI,_xlpm.TO+_xlpm.CG,_xlpm.CGT,MAX(0,MIN(_xlpm.HI,Tax!$B$18)-_xlpm.TO)*0+MAX(0,MIN(_xlpm.HI,Tax!$B$19)-MAX(_xlpm.TO,Tax!$B$18))*0.15+MAX(0,_xlpm.HI-MAX(_xlpm.TO,Tax!$B$19))*0.2,_xlpm.MAGI,_xlpm.PT+_xlpm.TSS+_xlpm.CG,_xlpm.NIIT,MAX(0,MIN(_xlpm.CG,_xlpm.MAGI-Tax!$B$20))*0.038,_xlpm.OT+_xlpm.CGT+_xlpm.NIIT)),_xlpm.Taxes,_xlfn.MAP(_xlpm.SpendWDs,_xlpm.Convs,_xlpm.BRs,_xlfn.LAMBDA(_xlpm.WD,_xlpm.Conv,_xlpm.BR,_xlpm.TAX(_xlpm.WD+_xlpm.Conv,_xlpm.BR))),_xlpm.TotalBals,_xlfn.SCAN('Retirement Gap'!$B$30,_xlpm.Taxes,_xlfn.LAMBDA(_xlpm.Open,_xlpm.Tx,MAX(0,_xlpm.Open*(1+_xlpm.R)-$B$10-_xlpm.Tx))),INDEX(_xlpm.TotalBals,_xlpm.N))} -> 1000811 | AR2: {=_xlfn.LET(_xlpm.N,$B$49,_xlpm.R,$B$48,_xlpm.Start,$B$47,_xlpm.PlanWD,AL2,_xlpm.PlanRoth,AM2,_xlpm.PlanConv,AN2,_xlpm.Ages,Inputs!$B$8+_xlfn.SEQUENCE(_xlpm.N)-1,_xlpm.Bals,_xlfn.SCAN(_xlpm.Start,_xlfn.SEQUENCE(_xlpm.N),_xlfn.LAMBDA(_xlpm.Open,_xlpm.i,_xlfn.LET(_xlpm.Age,Inputs!$B$8+_xlpm.i-1,_xlpm.Factor,_xlfn.XLOOKUP(_xlpm.Age,RMD!$A$21:$A$69,RMD!$B$21:$B$69,0),_xlpm.Req,IF(AND(_xlpm.Age>=RMD!$B$9,_xlpm.Factor>0),_xlpm.Open/_xlpm.Factor,0),_xlpm.SpendWD,MIN(_xlpm.Open,MAX(_xlpm.PlanWD,_xlpm.Req)),_xlpm.Conv,MIN(MAX(0,_xlpm.Open-_xlpm.SpendWD),_xlpm.PlanConv),MAX(0,_xlpm.Open*(1+_xlpm.R)-_xlpm.SpendWD-_xlpm.Conv)))),INDEX(_xlpm.Bals,_xlpm.N))} -> 1251763 | AS2: =--AND(AK2<=SUM('Retirement Gap'!$B$24:$B$25,'Retirement Gap'!$B$27),AL2+AN2<=$B$47,AM2<='Retirement Gap'!$B$29,ABS(AK2+AL2+AM2-$B$10)<1) -> 0 | AT2: {=IF(AS2=0,1E+99,_xlfn.SWITCH(LEFT($E$39,1),"1",AO2,"2",AP2*1000000000+AO2,"3",-AQ2,"4",AO2+AP2*25000+AR2*0.005-AQ2*0.0001,AO2))} -> 1e+99
A3: PURPOSE | AG3: =ROW()-1 -> 2 | AH3: =INT((AG3-1)/66)/10 -> 0 | AI3: =MOD(INT((AG3-1)/6),11)/10 -> 0 | AJ3: =MOD(AG3-1,6)/5 -> 0.2 | AK3: =MAX(0,$B$10-AL3-AM3) -> 60744 | AL3: =MIN($B$10*AH3,$B$47) -> 0 | AM3: =MIN(MAX(0,$B$10-AL3)*AI3,'Retirement Gap'!$B$29) -> 0 | AN3: =IF($E$40="B - Withdrawals + Roth conversions",AJ3*MAX(0,MIN($B$47-AL3,MIN($B$59,IRMAA!$C$16)-(AL3+$B$8*0.85+AK3*$B$46))),0) -> 0 | AO3: {=_xlfn.LET(_xlpm.N,$B$49,_xlpm.R,$B$48,_xlpm.Start,$B$47,_xlpm.PlanWD,AL3,_xlpm.PlanRoth,AM3,_xlpm.PlanConv,AN3,_xlpm.Ages,Inputs!$B$8+_xlfn.SEQUENCE(_xlpm.N)-1,_xlpm.Bals,_xlfn.SCAN(_xlpm.Start,_xlfn.SEQUENCE(_xlpm.N),_xlfn.LAMBDA(_xlpm.Open,_xlpm.i,_xlfn.LET(_xlpm.Age,Inputs!$B$8+_xlpm.i-1,_xlpm.Factor,_xlfn.XLOOKUP(_xlpm.Age,RMD!$A$21:$A$69,RMD!$B$21:$B$69,0),_xlpm.Req,IF(AND(_xlpm.Age>=RMD!$B$9,_xlpm.Factor>0),_xlpm.Open/_xlpm.Factor,0),_xlpm.SpendWD,MIN(_xlpm.Open,MAX(_xlpm.PlanWD,_xlpm.Req)),_xlpm.Conv,MIN(MAX(0,_xlpm.Open-_xlpm.SpendWD),_xlpm.PlanConv),MAX(0,_xlpm.Open*(1+_xlpm.R)-_xlpm.SpendWD-_xlpm.Conv)))),_xlpm.Opens,_xlfn.MAP(_xlfn.SEQUENCE(_xlpm.N),_xlfn.LAMBDA(_xlpm.i,IF(_xlpm.i=1,_xlpm.Start,INDEX(_xlpm.Bals,_xlpm.i-1)))),_xlpm.Reqs,_xlfn.MAP(_xlpm.Opens,_xlpm.Ages,_xlfn.LAMBDA(_xlpm.Open,_xlpm.Age,_xlfn.LET(_xlpm.Factor,_xlfn.XLOOKUP(_xlpm.Age,RMD!$A$21:$A$69,RMD!$B$21:$B$69,0),IF(AND(_xlpm.Age>=RMD!$B$9,_xlpm.Factor>0),_xlpm.Open/_xlpm.Factor,0)))),_xlpm.SpendWDs,_xlfn.MAP(_xlpm.Opens,_xlpm.Reqs,_xlfn.LAMBDA(_xlpm.Open,_xlpm.Req,MIN(_xlpm.Open,MAX(_xlpm.PlanWD,_xlpm.Req)))),_xlpm.Convs,_xlfn.MAP(_xlpm.Opens,_xlpm.SpendWDs,_xlfn.LAMBDA(_xlpm.Open,_xlpm.WD,MIN(MAX(0,_xlpm.Open-_xlpm.WD),_xlpm.PlanConv))),_xlpm.BRs,_xlfn.MAP(_xlpm.SpendWDs,_xlfn.LAMBDA(_xlpm.WD,MAX(0,$B$10-_xlpm.WD-_xlpm.PlanRoth))),_xlpm.TAX,_xlfn.LAMBDA(_xlpm.PT,_xlpm.BR,_xlfn.LET(_xlpm.SS,$B$8,_xlpm.CG,_xlpm.BR*$B$46,_xlpm.Prov,_xlpm.PT+_xlpm.CG+_xlpm.SS*0.5,_xlpm.TSS,_xlpm.SS*IF(AND(Tax!$B$21<=0,Tax!$B$22<=0),IF(_xlpm.SS>0,0.85,0),IF(_xlpm.Prov<Tax!$B$21,0,IF(_xlpm.Prov<Tax!$B$22,0.5,0.85))),_xlpm.Ord,_xlpm.PT+_xlpm.TSS,_xlpm.TO,MAX(0,_xlpm.Ord-Tax!$B$10),_xlpm.OT,MAX(0,MIN(_xlpm.TO,Tax!$B$11))*0.1+MAX(0,MIN(_xlpm.TO,Tax!$B$12)-Tax!$B$11)*0.12+MAX(0,MIN(_xlpm.TO,Tax!$B$13)-Tax!$B$12)*0.22+MAX(0,MIN(_xlpm.TO,Tax!$B$14)-Tax!$B$13)*0.24+MAX(0,MIN(_xlpm.TO,Tax!$B$15)-Tax!$B$14)*0.32+MAX(0,MIN(_xlpm.TO,Tax!$B$16)-Tax!$B$15)*0.35+MAX(0,_xlpm.TO-Tax!$B$16)*0.37,_xlpm.HI,_xlpm.TO+_xlpm.CG,_xlpm.CGT,MAX(0,MIN(_xlpm.HI,Tax!$B$18)-_xlpm.TO)*0+MAX(0,MIN(_xlpm.HI,Tax!$B$19)-MAX(_xlpm.TO,Tax!$B$18))*0.15+MAX(0,_xlpm.HI-MAX(_xlpm.TO,Tax!$B$19))*0.2,_xlpm.MAGI,_xlpm.PT+_xlpm.TSS+_xlpm.CG,_xlpm.NIIT,MAX(0,MIN(_xlpm.CG,_xlpm.MAGI-Tax!$B$20))*0.038,_xlpm.OT+_xlpm.CGT+_xlpm.NIIT)),_xlpm.Taxes,_xlfn.MAP(_xlpm.SpendWDs,_xlpm.Convs,_xlpm.BRs,_xlfn.LAMBDA(_xlpm.WD,_xlpm.Conv,_xlpm.BR,_xlpm.TAX(_xlpm.WD+_xlpm.Conv,_xlpm.BR))),SUM(_xlpm.Taxes))} -> 9083.8 | AP3: {=_xlfn.LET(_xlpm.N,$B$49,_xlpm.R,$B$48,_xlpm.Start,$B$47,_xlpm.PlanWD,AL3,_xlpm.PlanRoth,AM3,_xlpm.PlanConv,AN3,_xlpm.Ages,Inputs!$B$8+_xlfn.SEQUENCE(_xlpm.N)-1,_xlpm.Bals,_xlfn.SCAN(_xlpm.Start,_xlfn.SEQUENCE(_xlpm.N),_xlfn.LAMBDA(_xlpm.Open,_xlpm.i,_xlfn.LET(_xlpm.Age,Inputs!$B$8+_xlpm.i-1,_xlpm.Factor,_xlfn.XLOOKUP(_xlpm.Age,RMD!$A$21:$A$69,RMD!$B$21:$B$69,0),_xlpm.Req,IF(AND(_xlpm.Age>=RMD!$B$9,_xlpm.Factor>0),_xlpm.Open/_xlpm.Factor,0),_xlpm.SpendWD,MIN(_xlpm.Open,MAX(_xlpm.PlanWD,_xlpm.Req)),_xlpm.Conv,MIN(MAX(0,_xlpm.Open-_xlpm.SpendWD),_xlpm.PlanConv),MAX(0,_xlpm.Open*(1+_xlpm.R)-_xlpm.SpendWD-_xlpm.Conv)))),_xlpm.Opens,_xlfn.MAP(_xlfn.SEQUENCE(_xlpm.N),_xlfn.LAMBDA(_xlpm.i,IF(_xlpm.i=1,_xlpm.Start,INDEX(_xlpm.Bals,_xlpm.i-1)))),_xlpm.Reqs,_xlfn.MAP(_xlpm.Opens,_xlpm.Ages,_xlfn.LAMBDA(_xlpm.Open,_xlpm.Age,_xlfn.LET(_xlpm.Factor,_xlfn.XLOOKUP(_xlpm.Age,RMD!$A$21:$A$69,RMD!$B$21:$B$69,0),IF(AND(_xlpm.Age>=RMD!$B$9,_xlpm.Factor>0),_xlpm.Open/_xlpm.Factor,0)))),_xlpm.SpendWDs,_xlfn.MAP(_xlpm.Opens,_xlpm.Reqs,_xlfn.LAMBDA(_xlpm.Open,_xlpm.Req,MIN(_xlpm.Open,MAX(_xlpm.PlanWD,_xlpm.Req)))),_xlpm.Convs,_xlfn.MAP(_xlpm.Opens,_xlpm.SpendWDs,_xlfn.LAMBDA(_xlpm.Open,_xlpm.WD,MIN(MAX(0,_xlpm.Open-_xlpm.WD),_xlpm.PlanConv))),_xlpm.BRs,_xlfn.MAP(_xlpm.SpendWDs,_xlfn.LAMBDA(_xlpm.WD,MAX(0,$B$10-_xlpm.WD-_xlpm.PlanRoth))),_xlpm.TIER,_xlfn.LAMBDA(_xlpm.PT,_xlpm.BR,_xlfn.LET(_xlpm.SS,$B$8,_xlpm.CG,_xlpm.BR*$B$46,_xlpm.Prov,_xlpm.PT+_xlpm.CG+_xlpm.SS*0.5,_xlpm.TSS,_xlpm.SS*IF(AND(Tax!$B$21<=0,Tax!$B$22<=0),IF(_xlpm.SS>0,0.85,0),IF(_xlpm.Prov<Tax!$B$21,0,IF(_xlpm.Prov<Tax!$B$22,0.5,0.85))),_xlpm.MAGI,_xlpm.PT+_xlpm.TSS+_xlpm.CG,LOOKUP(_xlpm.MAGI,IRMAA!$B$16:$B$21,IRMAA!$A$16:$A$21))),_xlpm.Tiers,_xlfn.MAP(_xlpm.SpendWDs,_xlpm.Convs,_xlpm.BRs,_xlfn.LAMBDA(_xlpm.WD,_xlpm.Conv,_xlpm.BR,_xlpm.TIER(_xlpm.WD+_xlpm.Conv,_xlpm.BR))),MAX(_xlpm.Tiers))} -> 0 | AQ3: {=_xlfn.LET(_xlpm.N,$B$49,_xlpm.R,$B$48,_xlpm.Start,$B$47,_xlpm.PlanWD,AL3,_xlpm.PlanRoth,AM3,_xlpm.PlanConv,AN3,_xlpm.Ages,Inputs!$B$8+_xlfn.SEQUENCE(_xlpm.N)-1,_xlpm.Bals,_xlfn.SCAN(_xlpm.Start,_xlfn.SEQUENCE(_xlpm.N),_xlfn.LAMBDA(_xlpm.Open,_xlpm.i,_xlfn.LET(_xlpm.Age,Inputs!$B$8+_xlpm.i-1,_xlpm.Factor,_xlfn.XLOOKUP(_xlpm.Age,RMD!$A$21:$A$69,RMD!$B$21:$B$69,0),_xlpm.Req,IF(AND(_xlpm.Age>=RMD!$B$9,_xlpm.Factor>0),_xlpm.Open/_xlpm.Factor,0),_xlpm.SpendWD,MIN(_xlpm.Open,MAX(_xlpm.PlanWD,_xlpm.Req)),_xlpm.Conv,MIN(MAX(0,_xlpm.Open-_xlpm.SpendWD),_xlpm.PlanConv),MAX(0,_xlpm.Open*(1+_xlpm.R)-_xlpm.SpendWD-_xlpm.Conv)))),_xlpm.Opens,_xlfn.MAP(_xlfn.SEQUENCE(_xlpm.N),_xlfn.LAMBDA(_xlpm.i,IF(_xlpm.i=1,_xlpm.Start,INDEX(_xlpm.Bals,_xlpm.i-1)))),_xlpm.Reqs,_xlfn.MAP(_xlpm.Opens,_xlpm.Ages,_xlfn.LAMBDA(_xlpm.Open,_xlpm.Age,_xlfn.LET(_xlpm.Factor,_xlfn.XLOOKUP(_xlpm.Age,RMD!$A$21:$A$69,RMD!$B$21:$B$69,0),IF(AND(_xlpm.Age>=RMD!$B$9,_xlpm.Factor>0),_xlpm.Open/_xlpm.Factor,0)))),_xlpm.SpendWDs,_xlfn.MAP(_xlpm.Opens,_xlpm.Reqs,_xlfn.LAMBDA(_xlpm.Open,_xlpm.Req,MIN(_xlpm.Open,MAX(_xlpm.PlanWD,_xlpm.Req)))),_xlpm.Convs,_xlfn.MAP(_xlpm.Opens,_xlpm.SpendWDs,_xlfn.LAMBDA(_xlpm.Open,_xlpm.WD,MIN(MAX(0,_xlpm.Open-_xlpm.WD),_xlpm.PlanConv))),_xlpm.BRs,_xlfn.MAP(_xlpm.SpendWDs,_xlfn.LAMBDA(_xlpm.WD,MAX(0,$B$10-_xlpm.WD-_xlpm.PlanRoth))),_xlpm.TAX,_xlfn.LAMBDA(_xlpm.PT,_xlpm.BR,_xlfn.LET(_xlpm.SS,$B$8,_xlpm.CG,_xlpm.BR*$B$46,_xlpm.Prov,_xlpm.PT+_xlpm.CG+_xlpm.SS*0.5,_xlpm.TSS,_xlpm.SS*IF(AND(Tax!$B$21<=0,Tax!$B$22<=0),IF(_xlpm.SS>0,0.85,0),IF(_xlpm.Prov<Tax!$B$21,0,IF(_xlpm.Prov<Tax!$B$22,0.5,0.85))),_xlpm.Ord,_xlpm.PT+_xlpm.TSS,_xlpm.TO,MAX(0,_xlpm.Ord-Tax!$B$10),_xlpm.OT,MAX(0,MIN(_xlpm.TO,Tax!$B$11))*0.1+MAX(0,MIN(_xlpm.TO,Tax!$B$12)-Tax!$B$11)*0.12+MAX(0,MIN(_xlpm.TO,Tax!$B$13)-Tax!$B$12)*0.22+MAX(0,MIN(_xlpm.TO,Tax!$B$14)-Tax!$B$13)*0.24+MAX(0,MIN(_xlpm.TO,Tax!$B$15)-Tax!$B$14)*0.32+MAX(0,MIN(_xlpm.TO,Tax!$B$16)-Tax!$B$15)*0.35+MAX(0,_xlpm.TO-Tax!$B$16)*0.37,_xlpm.HI,_xlpm.TO+_xlpm.CG,_xlpm.CGT,MAX(0,MIN(_xlpm.HI,Tax!$B$18)-_xlpm.TO)*0+MAX(0,MIN(_xlpm.HI,Tax!$B$19)-MAX(_xlpm.TO,Tax!$B$18))*0.15+MAX(0,_xlpm.HI-MAX(_xlpm.TO,Tax!$B$19))*0.2,_xlpm.MAGI,_xlpm.PT+_xlpm.TSS+_xlpm.CG,_xlpm.NIIT,MAX(0,MIN(_xlpm.CG,_xlpm.MAGI-Tax!$B$20))*0.038,_xlpm.OT+_xlpm.CGT+_xlpm.NIIT)),_xlpm.Taxes,_xlfn.MAP(_xlpm.SpendWDs,_xlpm.Convs,_xlpm.BRs,_xlfn.LAMBDA(_xlpm.WD,_xlpm.Conv,_xlpm.BR,_xlpm.TAX(_xlpm.WD+_xlpm.Conv,_xlpm.BR))),_xlpm.TotalBals,_xlfn.SCAN('Retirement Gap'!$B$30,_xlpm.Taxes,_xlfn.LAMBDA(_xlpm.Open,_xlpm.Tx,MAX(0,_xlpm.Open*(1+_xlpm.R)-$B$10-_xlpm.Tx))),INDEX(_xlpm.TotalBals,_xlpm.N))} -> 1000811 | AR3: {=_xlfn.LET(_xlpm.N,$B$49,_xlpm.R,$B$48,_xlpm.Start,$B$47,_xlpm.PlanWD,AL3,_xlpm.PlanRoth,AM3,_xlpm.PlanConv,AN3,_xlpm.Ages,Inputs!$B$8+_xlfn.SEQUENCE(_xlpm.N)-1,_xlpm.Bals,_xlfn.SCAN(_xlpm.Start,_xlfn.SEQUENCE(_xlpm.N),_xlfn.LAMBDA(_xlpm.Open,_xlpm.i,_xlfn.LET(_xlpm.Age,Inputs!$B$8+_xlpm.i-1,_xlpm.Factor,_xlfn.XLOOKUP(_xlpm.Age,RMD!$A$21:$A$69,RMD!$B$21:$B$69,0),_xlpm.Req,IF(AND(_xlpm.Age>=RMD!$B$9,_xlpm.Factor>0),_xlpm.Open/_xlpm.Factor,0),_xlpm.SpendWD,MIN(_xlpm.Open,MAX(_xlpm.PlanWD,_xlpm.Req)),_xlpm.Conv,MIN(MAX(0,_xlpm.Open-_xlpm.SpendWD),_xlpm.PlanConv),MAX(0,_xlpm.Open*(1+_xlpm.R)-_xlpm.SpendWD-_xlpm.Conv)))),INDEX(_xlpm.Bals,_xlpm.N))} -> 1251763 | AS3: =--AND(AK3<=SUM('Retirement Gap'!$B$24:$B$25,'Retirement Gap'!$B$27),AL3+AN3<=$B$47,AM3<='Retirement Gap'!$B$29,ABS(AK3+AL3+AM3-$B$10)<1) -> 0 | AT3: {=IF(AS3=0,1E+99,_xlfn.SWITCH(LEFT($E$39,1),"1",AO3,"2",AP3*1000000000+AO3,"3",-AQ3,"4",AO3+AP3*25000+AR3*0.005-AQ3*0.0001,AO3))} -> 1e+99
